[2024-06-20T13:28:56.184+0000] {local_task_job_runner.py:120} INFO - ::group::Pre task execution logs
[2024-06-20T13:28:56.199+0000] {taskinstance.py:2076} INFO - Dependencies all met for dep_context=non-requeueable deps ti=<TaskInstance: emailtest23.send_email manual__2024-06-20T13:28:30.656387+00:00 [queued]>
[2024-06-20T13:28:56.204+0000] {taskinstance.py:2076} INFO - Dependencies all met for dep_context=requeueable deps ti=<TaskInstance: emailtest23.send_email manual__2024-06-20T13:28:30.656387+00:00 [queued]>
[2024-06-20T13:28:56.204+0000] {taskinstance.py:2306} INFO - Starting attempt 1 of 2
[2024-06-20T13:28:56.212+0000] {taskinstance.py:2330} INFO - Executing <Task(EmailOperator): send_email> on 2024-06-20 13:28:30.656387+00:00
[2024-06-20T13:28:56.217+0000] {warnings.py:112} WARNING - /home/***/.local/lib/python3.12/site-packages/***/task/task_runner/standard_task_runner.py:61: DeprecationWarning: This process (pid=410) is multi-threaded, use of fork() may lead to deadlocks in the child.
  pid = os.fork()

[2024-06-20T13:28:56.218+0000] {standard_task_runner.py:63} INFO - Started process 411 to run task
[2024-06-20T13:28:56.218+0000] {standard_task_runner.py:90} INFO - Running: ['***', 'tasks', 'run', 'emailtest23', 'send_email', 'manual__2024-06-20T13:28:30.656387+00:00', '--job-id', '334', '--raw', '--subdir', 'DAGS_FOLDER/emailtest.py', '--cfg-path', '/tmp/tmpdlptcmor']
[2024-06-20T13:28:56.219+0000] {standard_task_runner.py:91} INFO - Job 334: Subtask send_email
[2024-06-20T13:28:56.244+0000] {task_command.py:426} INFO - Running <TaskInstance: emailtest23.send_email manual__2024-06-20T13:28:30.656387+00:00 [running]> on host 3f2e9f854293
[2024-06-20T13:28:56.293+0000] {taskinstance.py:2648} INFO - Exporting env vars: AIRFLOW_CTX_DAG_EMAIL='liviataina.ltab@gmail.com' AIRFLOW_CTX_DAG_OWNER='***' AIRFLOW_CTX_DAG_ID='emailtest23' AIRFLOW_CTX_TASK_ID='send_email' AIRFLOW_CTX_EXECUTION_DATE='2024-06-20T13:28:30.656387+00:00' AIRFLOW_CTX_TRY_NUMBER='1' AIRFLOW_CTX_DAG_RUN_ID='manual__2024-06-20T13:28:30.656387+00:00'
[2024-06-20T13:28:56.293+0000] {taskinstance.py:430} INFO - ::endgroup::
[2024-06-20T13:28:56.307+0000] {base.py:84} INFO - Using connection ID 'smtp_default' for task execution.
[2024-06-20T13:28:56.307+0000] {email.py:271} INFO - Email alerting: attempt 1
[2024-06-20T13:29:00.110+0000] {taskinstance.py:441} INFO - ::group::Post task execution logs
[2024-06-20T13:29:00.111+0000] {taskinstance.py:2905} ERROR - Task failed with exception
Traceback (most recent call last):
  File "/home/airflow/.local/lib/python3.12/site-packages/airflow/models/taskinstance.py", line 465, in _execute_task
    result = _execute_callable(context=context, **execute_callable_kwargs)
             ^^^^^^^^^^^^^^^^^^^^^^^^^^^^^^^^^^^^^^^^^^^^^^^^^^^^^^^^^^^^^
  File "/home/airflow/.local/lib/python3.12/site-packages/airflow/models/taskinstance.py", line 432, in _execute_callable
    return execute_callable(context=context, **execute_callable_kwargs)
           ^^^^^^^^^^^^^^^^^^^^^^^^^^^^^^^^^^^^^^^^^^^^^^^^^^^^^^^^^^^^
  File "/home/airflow/.local/lib/python3.12/site-packages/airflow/models/baseoperator.py", line 401, in wrapper
    return func(self, *args, **kwargs)
           ^^^^^^^^^^^^^^^^^^^^^^^^^^^
  File "/home/airflow/.local/lib/python3.12/site-packages/airflow/operators/email.py", line 79, in execute
    send_email(
  File "/home/airflow/.local/lib/python3.12/site-packages/airflow/utils/email.py", line 80, in send_email
    return backend(
           ^^^^^^^^
  File "/home/airflow/.local/lib/python3.12/site-packages/airflow/utils/email.py", line 154, in send_email_smtp
    send_mime_email(e_from=mail_from, e_to=recipients, mime_msg=msg, conn_id=conn_id, dryrun=dryrun)
  File "/home/airflow/.local/lib/python3.12/site-packages/airflow/utils/email.py", line 281, in send_mime_email
    smtp_conn.login(smtp_user, smtp_password)
  File "/usr/local/lib/python3.12/smtplib.py", line 750, in login
    raise last_exception
  File "/usr/local/lib/python3.12/smtplib.py", line 739, in login
    (code, resp) = self.auth(
                   ^^^^^^^^^^
  File "/usr/local/lib/python3.12/smtplib.py", line 662, in auth
    raise SMTPAuthenticationError(code, resp)
smtplib.SMTPAuthenticationError: (535, b'5.7.8 Username and Password not accepted. For more information, go to\n5.7.8  https://support.google.com/mail/?p=BadCredentials d9443c01a7336-1f855f497a1sm136412155ad.283 - gsmtp')
[2024-06-20T13:29:00.131+0000] {taskinstance.py:1206} INFO - Marking task as UP_FOR_RETRY. dag_id=emailtest23, task_id=send_email, run_id=manual__2024-06-20T13:28:30.656387+00:00, execution_date=20240620T132830, start_date=20240620T132856, end_date=20240620T132900
[2024-06-20T13:29:00.151+0000] {standard_task_runner.py:110} ERROR - Failed to execute job 334 for task send_email ((535, b'5.7.8 Username and Password not accepted. For more information, go to\n5.7.8  https://support.google.com/mail/?p=BadCredentials d9443c01a7336-1f855f497a1sm136412155ad.283 - gsmtp'); 411)
[2024-06-20T13:29:00.161+0000] {local_task_job_runner.py:240} INFO - Task exited with return code 1
[2024-06-20T13:29:00.185+0000] {taskinstance.py:3503} INFO - 0 downstream tasks scheduled from follow-on schedule check
[2024-06-20T13:29:00.187+0000] {local_task_job_runner.py:222} INFO - ::endgroup::
