[2024-06-20T12:40:44.567+0000] {local_task_job_runner.py:120} INFO - ::group::Pre task execution logs
[2024-06-20T12:40:44.583+0000] {taskinstance.py:2076} INFO - Dependencies all met for dep_context=non-requeueable deps ti=<TaskInstance: emailtest19.task4 manual__2024-06-20T12:40:28.380229+00:00 [queued]>
[2024-06-20T12:40:44.588+0000] {taskinstance.py:2076} INFO - Dependencies all met for dep_context=requeueable deps ti=<TaskInstance: emailtest19.task4 manual__2024-06-20T12:40:28.380229+00:00 [queued]>
[2024-06-20T12:40:44.589+0000] {taskinstance.py:2306} INFO - Starting attempt 2 of 2
[2024-06-20T12:40:44.598+0000] {taskinstance.py:2330} INFO - Executing <Task(BashOperator): task4> on 2024-06-20 12:40:28.380229+00:00
[2024-06-20T12:40:44.602+0000] {warnings.py:112} WARNING - /home/***/.local/lib/python3.12/site-packages/***/task/task_runner/standard_task_runner.py:61: DeprecationWarning: This process (pid=238) is multi-threaded, use of fork() may lead to deadlocks in the child.
  pid = os.fork()

[2024-06-20T12:40:44.603+0000] {standard_task_runner.py:63} INFO - Started process 239 to run task
[2024-06-20T12:40:44.603+0000] {standard_task_runner.py:90} INFO - Running: ['***', 'tasks', 'run', 'emailtest19', 'task4', 'manual__2024-06-20T12:40:28.380229+00:00', '--job-id', '296', '--raw', '--subdir', 'DAGS_FOLDER/emailtest.py', '--cfg-path', '/tmp/tmpob1w_wqu']
[2024-06-20T12:40:44.604+0000] {standard_task_runner.py:91} INFO - Job 296: Subtask task4
[2024-06-20T12:40:44.630+0000] {task_command.py:426} INFO - Running <TaskInstance: emailtest19.task4 manual__2024-06-20T12:40:28.380229+00:00 [running]> on host c8ed831d9a3e
[2024-06-20T12:40:44.672+0000] {taskinstance.py:2648} INFO - Exporting env vars: AIRFLOW_CTX_DAG_EMAIL='liviataina.ltab@gmail.com' AIRFLOW_CTX_DAG_OWNER='***' AIRFLOW_CTX_DAG_ID='emailtest19' AIRFLOW_CTX_TASK_ID='task4' AIRFLOW_CTX_EXECUTION_DATE='2024-06-20T12:40:28.380229+00:00' AIRFLOW_CTX_TRY_NUMBER='2' AIRFLOW_CTX_DAG_RUN_ID='manual__2024-06-20T12:40:28.380229+00:00'
[2024-06-20T12:40:44.672+0000] {taskinstance.py:430} INFO - ::endgroup::
[2024-06-20T12:40:44.680+0000] {subprocess.py:63} INFO - Tmp dir root location: /tmp
[2024-06-20T12:40:44.681+0000] {subprocess.py:75} INFO - Running command: ['/usr/bin/bash', '-c', 'exit 1']
[2024-06-20T12:40:44.687+0000] {subprocess.py:86} INFO - Output:
[2024-06-20T12:40:44.688+0000] {subprocess.py:97} INFO - Command exited with return code 1
[2024-06-20T12:40:44.689+0000] {taskinstance.py:441} INFO - ::group::Post task execution logs
[2024-06-20T12:40:44.695+0000] {taskinstance.py:2905} ERROR - Task failed with exception
Traceback (most recent call last):
  File "/home/airflow/.local/lib/python3.12/site-packages/airflow/models/taskinstance.py", line 465, in _execute_task
    result = _execute_callable(context=context, **execute_callable_kwargs)
             ^^^^^^^^^^^^^^^^^^^^^^^^^^^^^^^^^^^^^^^^^^^^^^^^^^^^^^^^^^^^^
  File "/home/airflow/.local/lib/python3.12/site-packages/airflow/models/taskinstance.py", line 432, in _execute_callable
    return execute_callable(context=context, **execute_callable_kwargs)
           ^^^^^^^^^^^^^^^^^^^^^^^^^^^^^^^^^^^^^^^^^^^^^^^^^^^^^^^^^^^^
  File "/home/airflow/.local/lib/python3.12/site-packages/airflow/models/baseoperator.py", line 401, in wrapper
    return func(self, *args, **kwargs)
           ^^^^^^^^^^^^^^^^^^^^^^^^^^^
  File "/home/airflow/.local/lib/python3.12/site-packages/airflow/operators/bash.py", line 243, in execute
    raise AirflowException(
airflow.exceptions.AirflowException: Bash command failed. The command returned a non-zero exit code 1.
[2024-06-20T12:40:44.697+0000] {taskinstance.py:1206} INFO - Marking task as FAILED. dag_id=emailtest19, task_id=task4, run_id=manual__2024-06-20T12:40:28.380229+00:00, execution_date=20240620T124028, start_date=20240620T124044, end_date=20240620T124044
[2024-06-20T12:40:44.707+0000] {base.py:84} INFO - Using connection ID 'smtp_default' for task execution.
[2024-06-20T12:40:44.707+0000] {email.py:271} INFO - Email alerting: attempt 1
[2024-06-20T12:40:48.698+0000] {base.py:84} INFO - Using connection ID 'smtp_default' for task execution.
[2024-06-20T12:40:48.699+0000] {email.py:271} INFO - Email alerting: attempt 1
[2024-06-20T12:40:52.963+0000] {taskinstance.py:879} ERROR - Failed to send email to: ['liviataina.ltab@gmail.com']
Traceback (most recent call last):
  File "/home/airflow/.local/lib/python3.12/site-packages/airflow/models/taskinstance.py", line 2479, in _run_raw_task
    self._execute_task_with_callbacks(context, test_mode, session=session)
  File "/home/airflow/.local/lib/python3.12/site-packages/airflow/models/taskinstance.py", line 2676, in _execute_task_with_callbacks
    result = self._execute_task(context, task_orig)
             ^^^^^^^^^^^^^^^^^^^^^^^^^^^^^^^^^^^^^^
  File "/home/airflow/.local/lib/python3.12/site-packages/airflow/models/taskinstance.py", line 2701, in _execute_task
    return _execute_task(self, context, task_orig)
           ^^^^^^^^^^^^^^^^^^^^^^^^^^^^^^^^^^^^^^^
  File "/home/airflow/.local/lib/python3.12/site-packages/airflow/models/taskinstance.py", line 465, in _execute_task
    result = _execute_callable(context=context, **execute_callable_kwargs)
             ^^^^^^^^^^^^^^^^^^^^^^^^^^^^^^^^^^^^^^^^^^^^^^^^^^^^^^^^^^^^^
  File "/home/airflow/.local/lib/python3.12/site-packages/airflow/models/taskinstance.py", line 432, in _execute_callable
    return execute_callable(context=context, **execute_callable_kwargs)
           ^^^^^^^^^^^^^^^^^^^^^^^^^^^^^^^^^^^^^^^^^^^^^^^^^^^^^^^^^^^^
  File "/home/airflow/.local/lib/python3.12/site-packages/airflow/models/baseoperator.py", line 401, in wrapper
    return func(self, *args, **kwargs)
           ^^^^^^^^^^^^^^^^^^^^^^^^^^^
  File "/home/airflow/.local/lib/python3.12/site-packages/airflow/operators/bash.py", line 243, in execute
    raise AirflowException(
airflow.exceptions.AirflowException: Bash command failed. The command returned a non-zero exit code 1.

During handling of the above exception, another exception occurred:

Traceback (most recent call last):
  File "/home/airflow/.local/lib/python3.12/site-packages/airflow/models/taskinstance.py", line 1063, in _email_alert
    send_email(task.email, subject, html_content)
  File "/home/airflow/.local/lib/python3.12/site-packages/airflow/utils/email.py", line 80, in send_email
    return backend(
           ^^^^^^^^
  File "/home/airflow/.local/lib/python3.12/site-packages/airflow/utils/email.py", line 154, in send_email_smtp
    send_mime_email(e_from=mail_from, e_to=recipients, mime_msg=msg, conn_id=conn_id, dryrun=dryrun)
  File "/home/airflow/.local/lib/python3.12/site-packages/airflow/utils/email.py", line 281, in send_mime_email
    smtp_conn.login(smtp_user, smtp_password)
  File "/usr/local/lib/python3.12/smtplib.py", line 750, in login
    raise last_exception
  File "/usr/local/lib/python3.12/smtplib.py", line 739, in login
    (code, resp) = self.auth(
                   ^^^^^^^^^^
  File "/usr/local/lib/python3.12/smtplib.py", line 662, in auth
    raise SMTPAuthenticationError(code, resp)
smtplib.SMTPAuthenticationError: (535, b'5.7.8 Username and Password not accepted. For more information, go to\n5.7.8  https://support.google.com/mail/?p=BadCredentials d2e1a72fcca58-705ccb3d1aasm12757637b3a.140 - gsmtp')

During handling of the above exception, another exception occurred:

Traceback (most recent call last):
  File "/home/airflow/.local/lib/python3.12/site-packages/airflow/models/taskinstance.py", line 877, in _handle_failure
    task_instance.email_alert(error, failure_context["task"])
  File "/home/airflow/.local/lib/python3.12/site-packages/airflow/models/taskinstance.py", line 3163, in email_alert
    _email_alert(task_instance=self, exception=exception, task=task)
  File "/home/airflow/.local/lib/python3.12/site-packages/airflow/models/taskinstance.py", line 1065, in _email_alert
    send_email(task.email, subject, html_content_err)
  File "/home/airflow/.local/lib/python3.12/site-packages/airflow/utils/email.py", line 80, in send_email
    return backend(
           ^^^^^^^^
  File "/home/airflow/.local/lib/python3.12/site-packages/airflow/utils/email.py", line 154, in send_email_smtp
    send_mime_email(e_from=mail_from, e_to=recipients, mime_msg=msg, conn_id=conn_id, dryrun=dryrun)
  File "/home/airflow/.local/lib/python3.12/site-packages/airflow/utils/email.py", line 281, in send_mime_email
    smtp_conn.login(smtp_user, smtp_password)
  File "/usr/local/lib/python3.12/smtplib.py", line 750, in login
    raise last_exception
  File "/usr/local/lib/python3.12/smtplib.py", line 739, in login
    (code, resp) = self.auth(
                   ^^^^^^^^^^
  File "/usr/local/lib/python3.12/smtplib.py", line 662, in auth
    raise SMTPAuthenticationError(code, resp)
smtplib.SMTPAuthenticationError: (535, b'5.7.8 Username and Password not accepted. For more information, go to\n5.7.8  https://support.google.com/mail/?p=BadCredentials 98e67ed59e1d1-2c7e56d5d70sm1587291a91.30 - gsmtp')
[2024-06-20T12:40:53.001+0000] {standard_task_runner.py:110} ERROR - Failed to execute job 296 for task task4 (Bash command failed. The command returned a non-zero exit code 1.; 239)
[2024-06-20T12:40:53.051+0000] {local_task_job_runner.py:240} INFO - Task exited with return code 1
[2024-06-20T12:40:53.092+0000] {taskinstance.py:3503} INFO - 1 downstream tasks scheduled from follow-on schedule check
[2024-06-20T12:40:53.095+0000] {local_task_job_runner.py:222} INFO - ::endgroup::
