[2024-06-20T12:21:57.847+0000] {local_task_job_runner.py:120} INFO - ::group::Pre task execution logs
[2024-06-20T12:21:57.861+0000] {taskinstance.py:2076} INFO - Dependencies all met for dep_context=non-requeueable deps ti=<TaskInstance: emailtest17.send_email manual__2024-06-20T12:21:32.305025+00:00 [queued]>
[2024-06-20T12:21:57.866+0000] {taskinstance.py:2076} INFO - Dependencies all met for dep_context=requeueable deps ti=<TaskInstance: emailtest17.send_email manual__2024-06-20T12:21:32.305025+00:00 [queued]>
[2024-06-20T12:21:57.866+0000] {taskinstance.py:2306} INFO - Starting attempt 1 of 2
[2024-06-20T12:21:57.875+0000] {taskinstance.py:2330} INFO - Executing <Task(EmailOperator): send_email> on 2024-06-20 12:21:32.305025+00:00
[2024-06-20T12:21:57.878+0000] {warnings.py:112} WARNING - /home/***/.local/lib/python3.12/site-packages/***/task/task_runner/standard_task_runner.py:61: DeprecationWarning: This process (pid=96) is multi-threaded, use of fork() may lead to deadlocks in the child.
  pid = os.fork()

[2024-06-20T12:21:57.879+0000] {standard_task_runner.py:63} INFO - Started process 97 to run task
[2024-06-20T12:21:57.879+0000] {standard_task_runner.py:90} INFO - Running: ['***', 'tasks', 'run', 'emailtest17', 'send_email', 'manual__2024-06-20T12:21:32.305025+00:00', '--job-id', '281', '--raw', '--subdir', 'DAGS_FOLDER/emailtest.py', '--cfg-path', '/tmp/tmpwk4ambmt']
[2024-06-20T12:21:57.880+0000] {standard_task_runner.py:91} INFO - Job 281: Subtask send_email
[2024-06-20T12:21:57.906+0000] {task_command.py:426} INFO - Running <TaskInstance: emailtest17.send_email manual__2024-06-20T12:21:32.305025+00:00 [running]> on host 29fb26d13ac3
[2024-06-20T12:21:57.963+0000] {taskinstance.py:2648} INFO - Exporting env vars: AIRFLOW_CTX_DAG_EMAIL='liviataina.ltab@gmail.com' AIRFLOW_CTX_DAG_OWNER='***' AIRFLOW_CTX_DAG_ID='emailtest17' AIRFLOW_CTX_TASK_ID='send_email' AIRFLOW_CTX_EXECUTION_DATE='2024-06-20T12:21:32.305025+00:00' AIRFLOW_CTX_TRY_NUMBER='1' AIRFLOW_CTX_DAG_RUN_ID='manual__2024-06-20T12:21:32.305025+00:00'
[2024-06-20T12:21:57.963+0000] {taskinstance.py:430} INFO - ::endgroup::
[2024-06-20T12:21:57.976+0000] {warnings.py:112} WARNING - /home/***/.local/lib/python3.12/site-packages/***/utils/email.py:154: RemovedInAirflow3Warning: Fetching SMTP credentials from configuration variables will be deprecated in a future release. Please set credentials using a connection instead.
  send_mime_email(e_from=mail_from, e_to=recipients, mime_msg=msg, conn_id=conn_id, dryrun=dryrun)

[2024-06-20T12:21:57.976+0000] {email.py:271} INFO - Email alerting: attempt 1
[2024-06-20T12:22:02.183+0000] {taskinstance.py:441} INFO - ::group::Post task execution logs
[2024-06-20T12:22:02.183+0000] {taskinstance.py:2905} ERROR - Task failed with exception
Traceback (most recent call last):
  File "/home/airflow/.local/lib/python3.12/site-packages/airflow/models/taskinstance.py", line 465, in _execute_task
    result = _execute_callable(context=context, **execute_callable_kwargs)
             ^^^^^^^^^^^^^^^^^^^^^^^^^^^^^^^^^^^^^^^^^^^^^^^^^^^^^^^^^^^^^
  File "/home/airflow/.local/lib/python3.12/site-packages/airflow/models/taskinstance.py", line 432, in _execute_callable
    return execute_callable(context=context, **execute_callable_kwargs)
           ^^^^^^^^^^^^^^^^^^^^^^^^^^^^^^^^^^^^^^^^^^^^^^^^^^^^^^^^^^^^
  File "/home/airflow/.local/lib/python3.12/site-packages/airflow/models/baseoperator.py", line 401, in wrapper
    return func(self, *args, **kwargs)
           ^^^^^^^^^^^^^^^^^^^^^^^^^^^
  File "/home/airflow/.local/lib/python3.12/site-packages/airflow/operators/email.py", line 79, in execute
    send_email(
  File "/home/airflow/.local/lib/python3.12/site-packages/airflow/utils/email.py", line 80, in send_email
    return backend(
           ^^^^^^^^
  File "/home/airflow/.local/lib/python3.12/site-packages/airflow/utils/email.py", line 154, in send_email_smtp
    send_mime_email(e_from=mail_from, e_to=recipients, mime_msg=msg, conn_id=conn_id, dryrun=dryrun)
  File "/home/airflow/.local/lib/python3.12/site-packages/airflow/utils/email.py", line 281, in send_mime_email
    smtp_conn.login(smtp_user, smtp_password)
  File "/usr/local/lib/python3.12/smtplib.py", line 750, in login
    raise last_exception
  File "/usr/local/lib/python3.12/smtplib.py", line 739, in login
    (code, resp) = self.auth(
                   ^^^^^^^^^^
  File "/usr/local/lib/python3.12/smtplib.py", line 662, in auth
    raise SMTPAuthenticationError(code, resp)
smtplib.SMTPAuthenticationError: (535, b'5.7.8 Username and Password not accepted. For more information, go to\n5.7.8  https://support.google.com/mail/?p=BadCredentials d9443c01a7336-1f855f5bb22sm136338475ad.302 - gsmtp')
[2024-06-20T12:22:02.189+0000] {taskinstance.py:1206} INFO - Marking task as UP_FOR_RETRY. dag_id=emailtest17, task_id=send_email, run_id=manual__2024-06-20T12:21:32.305025+00:00, execution_date=20240620T122132, start_date=20240620T122157, end_date=20240620T122202
[2024-06-20T12:22:02.197+0000] {standard_task_runner.py:110} ERROR - Failed to execute job 281 for task send_email ((535, b'5.7.8 Username and Password not accepted. For more information, go to\n5.7.8  https://support.google.com/mail/?p=BadCredentials d9443c01a7336-1f855f5bb22sm136338475ad.302 - gsmtp'); 97)
[2024-06-20T12:22:02.227+0000] {local_task_job_runner.py:240} INFO - Task exited with return code 1
[2024-06-20T12:22:02.237+0000] {taskinstance.py:3503} INFO - 0 downstream tasks scheduled from follow-on schedule check
[2024-06-20T12:22:02.238+0000] {local_task_job_runner.py:222} INFO - ::endgroup::
