[2024-06-19T14:28:53.287+0000] {local_task_job_runner.py:120} INFO - ::group::Pre task execution logs
[2024-06-19T14:28:53.302+0000] {taskinstance.py:2076} INFO - Dependencies all met for dep_context=non-requeueable deps ti=<TaskInstance: emailtest.send_email manual__2024-06-19T14:28:28.061994+00:00 [queued]>
[2024-06-19T14:28:53.306+0000] {taskinstance.py:2076} INFO - Dependencies all met for dep_context=requeueable deps ti=<TaskInstance: emailtest.send_email manual__2024-06-19T14:28:28.061994+00:00 [queued]>
[2024-06-19T14:28:53.306+0000] {taskinstance.py:2306} INFO - Starting attempt 1 of 2
[2024-06-19T14:28:53.315+0000] {taskinstance.py:2330} INFO - Executing <Task(EmailOperator): send_email> on 2024-06-19 14:28:28.061994+00:00
[2024-06-19T14:28:53.319+0000] {warnings.py:112} WARNING - /home/***/.local/lib/python3.12/site-packages/***/task/task_runner/standard_task_runner.py:61: DeprecationWarning: This process (pid=481) is multi-threaded, use of fork() may lead to deadlocks in the child.
  pid = os.fork()

[2024-06-19T14:28:53.319+0000] {standard_task_runner.py:63} INFO - Started process 482 to run task
[2024-06-19T14:28:53.320+0000] {standard_task_runner.py:90} INFO - Running: ['***', 'tasks', 'run', 'emailtest', 'send_email', 'manual__2024-06-19T14:28:28.061994+00:00', '--job-id', '145', '--raw', '--subdir', 'DAGS_FOLDER/emailtest.py', '--cfg-path', '/tmp/tmp5as5_efe']
[2024-06-19T14:28:53.320+0000] {standard_task_runner.py:91} INFO - Job 145: Subtask send_email
[2024-06-19T14:28:53.347+0000] {task_command.py:426} INFO - Running <TaskInstance: emailtest.send_email manual__2024-06-19T14:28:28.061994+00:00 [running]> on host c743c3172e67
[2024-06-19T14:28:53.396+0000] {taskinstance.py:2648} INFO - Exporting env vars: AIRFLOW_CTX_DAG_EMAIL='liviataina.ltab@gmail.com' AIRFLOW_CTX_DAG_OWNER='***' AIRFLOW_CTX_DAG_ID='emailtest' AIRFLOW_CTX_TASK_ID='send_email' AIRFLOW_CTX_EXECUTION_DATE='2024-06-19T14:28:28.061994+00:00' AIRFLOW_CTX_TRY_NUMBER='1' AIRFLOW_CTX_DAG_RUN_ID='manual__2024-06-19T14:28:28.061994+00:00'
[2024-06-19T14:28:53.396+0000] {taskinstance.py:430} INFO - ::endgroup::
[2024-06-19T14:28:53.410+0000] {warnings.py:112} WARNING - /home/***/.local/lib/python3.12/site-packages/***/utils/email.py:154: RemovedInAirflow3Warning: Fetching SMTP credentials from configuration variables will be deprecated in a future release. Please set credentials using a connection instead.
  send_mime_email(e_from=mail_from, e_to=recipients, mime_msg=msg, conn_id=conn_id, dryrun=dryrun)

[2024-06-19T14:28:53.410+0000] {email.py:271} INFO - Email alerting: attempt 1
[2024-06-19T14:28:57.573+0000] {taskinstance.py:441} INFO - ::group::Post task execution logs
[2024-06-19T14:28:57.574+0000] {taskinstance.py:2905} ERROR - Task failed with exception
Traceback (most recent call last):
  File "/home/airflow/.local/lib/python3.12/site-packages/airflow/models/taskinstance.py", line 465, in _execute_task
    result = _execute_callable(context=context, **execute_callable_kwargs)
             ^^^^^^^^^^^^^^^^^^^^^^^^^^^^^^^^^^^^^^^^^^^^^^^^^^^^^^^^^^^^^
  File "/home/airflow/.local/lib/python3.12/site-packages/airflow/models/taskinstance.py", line 432, in _execute_callable
    return execute_callable(context=context, **execute_callable_kwargs)
           ^^^^^^^^^^^^^^^^^^^^^^^^^^^^^^^^^^^^^^^^^^^^^^^^^^^^^^^^^^^^
  File "/home/airflow/.local/lib/python3.12/site-packages/airflow/models/baseoperator.py", line 401, in wrapper
    return func(self, *args, **kwargs)
           ^^^^^^^^^^^^^^^^^^^^^^^^^^^
  File "/home/airflow/.local/lib/python3.12/site-packages/airflow/operators/email.py", line 79, in execute
    send_email(
  File "/home/airflow/.local/lib/python3.12/site-packages/airflow/utils/email.py", line 80, in send_email
    return backend(
           ^^^^^^^^
  File "/home/airflow/.local/lib/python3.12/site-packages/airflow/utils/email.py", line 154, in send_email_smtp
    send_mime_email(e_from=mail_from, e_to=recipients, mime_msg=msg, conn_id=conn_id, dryrun=dryrun)
  File "/home/airflow/.local/lib/python3.12/site-packages/airflow/utils/email.py", line 281, in send_mime_email
    smtp_conn.login(smtp_user, smtp_password)
  File "/usr/local/lib/python3.12/smtplib.py", line 750, in login
    raise last_exception
  File "/usr/local/lib/python3.12/smtplib.py", line 739, in login
    (code, resp) = self.auth(
                   ^^^^^^^^^^
  File "/usr/local/lib/python3.12/smtplib.py", line 662, in auth
    raise SMTPAuthenticationError(code, resp)
smtplib.SMTPAuthenticationError: (535, b'5.7.8 Username and Password not accepted. For more information, go to\n5.7.8  https://support.google.com/mail/?p=BadCredentials d9443c01a7336-1f855e56183sm117427905ad.28 - gsmtp')
[2024-06-19T14:28:57.590+0000] {taskinstance.py:1206} INFO - Marking task as UP_FOR_RETRY. dag_id=emailtest, task_id=send_email, run_id=manual__2024-06-19T14:28:28.061994+00:00, execution_date=20240619T142828, start_date=20240619T142853, end_date=20240619T142857
[2024-06-19T14:28:57.607+0000] {standard_task_runner.py:110} ERROR - Failed to execute job 145 for task send_email ((535, b'5.7.8 Username and Password not accepted. For more information, go to\n5.7.8  https://support.google.com/mail/?p=BadCredentials d9443c01a7336-1f855e56183sm117427905ad.28 - gsmtp'); 482)
[2024-06-19T14:28:57.625+0000] {local_task_job_runner.py:240} INFO - Task exited with return code 1
[2024-06-19T14:28:57.646+0000] {taskinstance.py:3503} INFO - 0 downstream tasks scheduled from follow-on schedule check
[2024-06-19T14:28:57.649+0000] {local_task_job_runner.py:222} INFO - ::endgroup::
