[2024-06-21T13:19:51.221+0000] {local_task_job_runner.py:120} INFO - ::group::Pre task execution logs
[2024-06-21T13:19:51.233+0000] {taskinstance.py:2076} INFO - Dependencies all met for dep_context=non-requeueable deps ti=<TaskInstance: pythonoperator.data_cleanner_salary manual__2024-06-21T13:19:49.193929+00:00 [queued]>
[2024-06-21T13:19:51.237+0000] {taskinstance.py:2076} INFO - Dependencies all met for dep_context=requeueable deps ti=<TaskInstance: pythonoperator.data_cleanner_salary manual__2024-06-21T13:19:49.193929+00:00 [queued]>
[2024-06-21T13:19:51.237+0000] {taskinstance.py:2306} INFO - Starting attempt 1 of 1
[2024-06-21T13:19:51.244+0000] {taskinstance.py:2330} INFO - Executing <Task(PythonOperator): data_cleanner_salary> on 2024-06-21 13:19:49.193929+00:00
[2024-06-21T13:19:51.249+0000] {warnings.py:112} WARNING - /home/***/.local/lib/python3.12/site-packages/***/task/task_runner/standard_task_runner.py:61: DeprecationWarning: This process (pid=376) is multi-threaded, use of fork() may lead to deadlocks in the child.
  pid = os.fork()

[2024-06-21T13:19:51.250+0000] {standard_task_runner.py:63} INFO - Started process 378 to run task
[2024-06-21T13:19:51.250+0000] {standard_task_runner.py:90} INFO - Running: ['***', 'tasks', 'run', 'pythonoperator', 'data_cleanner_salary', 'manual__2024-06-21T13:19:49.193929+00:00', '--job-id', '411', '--raw', '--subdir', 'DAGS_FOLDER/pythonoperator.py', '--cfg-path', '/tmp/tmp_mlgwh4x']
[2024-06-21T13:19:51.251+0000] {standard_task_runner.py:91} INFO - Job 411: Subtask data_cleanner_salary
[2024-06-21T13:19:51.276+0000] {task_command.py:426} INFO - Running <TaskInstance: pythonoperator.data_cleanner_salary manual__2024-06-21T13:19:49.193929+00:00 [running]> on host a5e007d33222
[2024-06-21T13:19:51.346+0000] {taskinstance.py:2648} INFO - Exporting env vars: AIRFLOW_CTX_DAG_OWNER='***' AIRFLOW_CTX_DAG_ID='pythonoperator' AIRFLOW_CTX_TASK_ID='data_cleanner_salary' AIRFLOW_CTX_EXECUTION_DATE='2024-06-21T13:19:49.193929+00:00' AIRFLOW_CTX_TRY_NUMBER='1' AIRFLOW_CTX_DAG_RUN_ID='manual__2024-06-21T13:19:49.193929+00:00'
[2024-06-21T13:19:51.346+0000] {taskinstance.py:430} INFO - ::endgroup::
[2024-06-21T13:19:51.362+0000] {taskinstance.py:441} INFO - ::group::Post task execution logs
[2024-06-21T13:19:51.363+0000] {taskinstance.py:2905} ERROR - Task failed with exception
Traceback (most recent call last):
  File "/home/airflow/.local/lib/python3.12/site-packages/airflow/models/taskinstance.py", line 465, in _execute_task
    result = _execute_callable(context=context, **execute_callable_kwargs)
             ^^^^^^^^^^^^^^^^^^^^^^^^^^^^^^^^^^^^^^^^^^^^^^^^^^^^^^^^^^^^^
  File "/home/airflow/.local/lib/python3.12/site-packages/airflow/models/taskinstance.py", line 432, in _execute_callable
    return execute_callable(context=context, **execute_callable_kwargs)
           ^^^^^^^^^^^^^^^^^^^^^^^^^^^^^^^^^^^^^^^^^^^^^^^^^^^^^^^^^^^^
  File "/home/airflow/.local/lib/python3.12/site-packages/airflow/models/baseoperator.py", line 401, in wrapper
    return func(self, *args, **kwargs)
           ^^^^^^^^^^^^^^^^^^^^^^^^^^^
  File "/home/airflow/.local/lib/python3.12/site-packages/airflow/operators/python.py", line 235, in execute
    return_value = self.execute_callable()
                   ^^^^^^^^^^^^^^^^^^^^^^^
  File "/home/airflow/.local/lib/python3.12/site-packages/airflow/operators/python.py", line 252, in execute_callable
    return self.python_callable(*self.op_args, **self.op_kwargs)
           ^^^^^^^^^^^^^^^^^^^^^^^^^^^^^^^^^^^^^^^^^^^^^^^^^^^^^
  File "/opt/airflow/dags/pythonoperator.py", line 40, in data_cleanner_salary
    dataset.to_copy("/opt/airflow/data/Churn_treatment.csv", sep=";", index=False)
    ^^^^^^^^^^^^^^^
  File "/home/airflow/.local/lib/python3.12/site-packages/pandas/core/generic.py", line 6204, in __getattr__
    return object.__getattribute__(self, name)
           ^^^^^^^^^^^^^^^^^^^^^^^^^^^^^^^^^^^
AttributeError: 'DataFrame' object has no attribute 'to_copy'. Did you mean: '_is_copy'?
[2024-06-21T13:19:51.372+0000] {taskinstance.py:1206} INFO - Marking task as FAILED. dag_id=pythonoperator, task_id=data_cleanner_salary, run_id=manual__2024-06-21T13:19:49.193929+00:00, execution_date=20240621T131949, start_date=20240621T131951, end_date=20240621T131951
[2024-06-21T13:19:51.379+0000] {standard_task_runner.py:110} ERROR - Failed to execute job 411 for task data_cleanner_salary ('DataFrame' object has no attribute 'to_copy'; 378)
[2024-06-21T13:19:51.423+0000] {local_task_job_runner.py:240} INFO - Task exited with return code 1
[2024-06-21T13:19:51.432+0000] {taskinstance.py:3503} INFO - 0 downstream tasks scheduled from follow-on schedule check
[2024-06-21T13:19:51.434+0000] {local_task_job_runner.py:222} INFO - ::endgroup::
