[2024-06-20T12:17:49.529+0000] {local_task_job_runner.py:120} INFO - ::group::Pre task execution logs
[2024-06-20T12:17:49.544+0000] {taskinstance.py:2076} INFO - Dependencies all met for dep_context=non-requeueable deps ti=<TaskInstance: emailtest16.task4 manual__2024-06-20T12:17:33.549629+00:00 [queued]>
[2024-06-20T12:17:49.549+0000] {taskinstance.py:2076} INFO - Dependencies all met for dep_context=requeueable deps ti=<TaskInstance: emailtest16.task4 manual__2024-06-20T12:17:33.549629+00:00 [queued]>
[2024-06-20T12:17:49.549+0000] {taskinstance.py:2306} INFO - Starting attempt 2 of 2
[2024-06-20T12:17:49.558+0000] {taskinstance.py:2330} INFO - Executing <Task(BashOperator): task4> on 2024-06-20 12:17:33.549629+00:00
[2024-06-20T12:17:49.562+0000] {warnings.py:112} WARNING - /home/***/.local/lib/python3.12/site-packages/***/task/task_runner/standard_task_runner.py:61: DeprecationWarning: This process (pid=423) is multi-threaded, use of fork() may lead to deadlocks in the child.
  pid = os.fork()

[2024-06-20T12:17:49.563+0000] {standard_task_runner.py:63} INFO - Started process 424 to run task
[2024-06-20T12:17:49.563+0000] {standard_task_runner.py:90} INFO - Running: ['***', 'tasks', 'run', 'emailtest16', 'task4', 'manual__2024-06-20T12:17:33.549629+00:00', '--job-id', '271', '--raw', '--subdir', 'DAGS_FOLDER/emailtest.py', '--cfg-path', '/tmp/tmp79ov_9h0']
[2024-06-20T12:17:49.564+0000] {standard_task_runner.py:91} INFO - Job 271: Subtask task4
[2024-06-20T12:17:49.590+0000] {task_command.py:426} INFO - Running <TaskInstance: emailtest16.task4 manual__2024-06-20T12:17:33.549629+00:00 [running]> on host f5fd5cda65b7
[2024-06-20T12:17:49.636+0000] {taskinstance.py:2648} INFO - Exporting env vars: AIRFLOW_CTX_DAG_EMAIL='liviataina.ltab@gmail.com' AIRFLOW_CTX_DAG_OWNER='***' AIRFLOW_CTX_DAG_ID='emailtest16' AIRFLOW_CTX_TASK_ID='task4' AIRFLOW_CTX_EXECUTION_DATE='2024-06-20T12:17:33.549629+00:00' AIRFLOW_CTX_TRY_NUMBER='2' AIRFLOW_CTX_DAG_RUN_ID='manual__2024-06-20T12:17:33.549629+00:00'
[2024-06-20T12:17:49.637+0000] {taskinstance.py:430} INFO - ::endgroup::
[2024-06-20T12:17:49.644+0000] {subprocess.py:63} INFO - Tmp dir root location: /tmp
[2024-06-20T12:17:49.645+0000] {subprocess.py:75} INFO - Running command: ['/usr/bin/bash', '-c', 'exit 1']
[2024-06-20T12:17:49.652+0000] {subprocess.py:86} INFO - Output:
[2024-06-20T12:17:49.653+0000] {subprocess.py:97} INFO - Command exited with return code 1
[2024-06-20T12:17:49.653+0000] {taskinstance.py:441} INFO - ::group::Post task execution logs
[2024-06-20T12:17:49.659+0000] {taskinstance.py:2905} ERROR - Task failed with exception
Traceback (most recent call last):
  File "/home/airflow/.local/lib/python3.12/site-packages/airflow/models/taskinstance.py", line 465, in _execute_task
    result = _execute_callable(context=context, **execute_callable_kwargs)
             ^^^^^^^^^^^^^^^^^^^^^^^^^^^^^^^^^^^^^^^^^^^^^^^^^^^^^^^^^^^^^
  File "/home/airflow/.local/lib/python3.12/site-packages/airflow/models/taskinstance.py", line 432, in _execute_callable
    return execute_callable(context=context, **execute_callable_kwargs)
           ^^^^^^^^^^^^^^^^^^^^^^^^^^^^^^^^^^^^^^^^^^^^^^^^^^^^^^^^^^^^
  File "/home/airflow/.local/lib/python3.12/site-packages/airflow/models/baseoperator.py", line 401, in wrapper
    return func(self, *args, **kwargs)
           ^^^^^^^^^^^^^^^^^^^^^^^^^^^
  File "/home/airflow/.local/lib/python3.12/site-packages/airflow/operators/bash.py", line 243, in execute
    raise AirflowException(
airflow.exceptions.AirflowException: Bash command failed. The command returned a non-zero exit code 1.
[2024-06-20T12:17:49.662+0000] {taskinstance.py:1206} INFO - Marking task as FAILED. dag_id=emailtest16, task_id=task4, run_id=manual__2024-06-20T12:17:33.549629+00:00, execution_date=20240620T121733, start_date=20240620T121749, end_date=20240620T121749
[2024-06-20T12:17:49.673+0000] {warnings.py:112} WARNING - /home/***/.local/lib/python3.12/site-packages/***/utils/email.py:154: RemovedInAirflow3Warning: Fetching SMTP credentials from configuration variables will be deprecated in a future release. Please set credentials using a connection instead.
  send_mime_email(e_from=mail_from, e_to=recipients, mime_msg=msg, conn_id=conn_id, dryrun=dryrun)

[2024-06-20T12:17:49.673+0000] {email.py:271} INFO - Email alerting: attempt 1
[2024-06-20T12:17:53.925+0000] {email.py:271} INFO - Email alerting: attempt 1
[2024-06-20T12:17:57.742+0000] {taskinstance.py:879} ERROR - Failed to send email to: ['liviataina.ltab@gmail.com']
Traceback (most recent call last):
  File "/home/airflow/.local/lib/python3.12/site-packages/airflow/models/taskinstance.py", line 2479, in _run_raw_task
    self._execute_task_with_callbacks(context, test_mode, session=session)
  File "/home/airflow/.local/lib/python3.12/site-packages/airflow/models/taskinstance.py", line 2676, in _execute_task_with_callbacks
    result = self._execute_task(context, task_orig)
             ^^^^^^^^^^^^^^^^^^^^^^^^^^^^^^^^^^^^^^
  File "/home/airflow/.local/lib/python3.12/site-packages/airflow/models/taskinstance.py", line 2701, in _execute_task
    return _execute_task(self, context, task_orig)
           ^^^^^^^^^^^^^^^^^^^^^^^^^^^^^^^^^^^^^^^
  File "/home/airflow/.local/lib/python3.12/site-packages/airflow/models/taskinstance.py", line 465, in _execute_task
    result = _execute_callable(context=context, **execute_callable_kwargs)
             ^^^^^^^^^^^^^^^^^^^^^^^^^^^^^^^^^^^^^^^^^^^^^^^^^^^^^^^^^^^^^
  File "/home/airflow/.local/lib/python3.12/site-packages/airflow/models/taskinstance.py", line 432, in _execute_callable
    return execute_callable(context=context, **execute_callable_kwargs)
           ^^^^^^^^^^^^^^^^^^^^^^^^^^^^^^^^^^^^^^^^^^^^^^^^^^^^^^^^^^^^
  File "/home/airflow/.local/lib/python3.12/site-packages/airflow/models/baseoperator.py", line 401, in wrapper
    return func(self, *args, **kwargs)
           ^^^^^^^^^^^^^^^^^^^^^^^^^^^
  File "/home/airflow/.local/lib/python3.12/site-packages/airflow/operators/bash.py", line 243, in execute
    raise AirflowException(
airflow.exceptions.AirflowException: Bash command failed. The command returned a non-zero exit code 1.

During handling of the above exception, another exception occurred:

Traceback (most recent call last):
  File "/home/airflow/.local/lib/python3.12/site-packages/airflow/models/taskinstance.py", line 1063, in _email_alert
    send_email(task.email, subject, html_content)
  File "/home/airflow/.local/lib/python3.12/site-packages/airflow/utils/email.py", line 80, in send_email
    return backend(
           ^^^^^^^^
  File "/home/airflow/.local/lib/python3.12/site-packages/airflow/utils/email.py", line 154, in send_email_smtp
    send_mime_email(e_from=mail_from, e_to=recipients, mime_msg=msg, conn_id=conn_id, dryrun=dryrun)
  File "/home/airflow/.local/lib/python3.12/site-packages/airflow/utils/email.py", line 281, in send_mime_email
    smtp_conn.login(smtp_user, smtp_password)
  File "/usr/local/lib/python3.12/smtplib.py", line 750, in login
    raise last_exception
  File "/usr/local/lib/python3.12/smtplib.py", line 739, in login
    (code, resp) = self.auth(
                   ^^^^^^^^^^
  File "/usr/local/lib/python3.12/smtplib.py", line 662, in auth
    raise SMTPAuthenticationError(code, resp)
smtplib.SMTPAuthenticationError: (535, b'5.7.8 Username and Password not accepted. For more information, go to\n5.7.8  https://support.google.com/mail/?p=BadCredentials d2e1a72fcca58-705ccb6b37asm12245716b3a.157 - gsmtp')

During handling of the above exception, another exception occurred:

Traceback (most recent call last):
  File "/home/airflow/.local/lib/python3.12/site-packages/airflow/models/taskinstance.py", line 877, in _handle_failure
    task_instance.email_alert(error, failure_context["task"])
  File "/home/airflow/.local/lib/python3.12/site-packages/airflow/models/taskinstance.py", line 3163, in email_alert
    _email_alert(task_instance=self, exception=exception, task=task)
  File "/home/airflow/.local/lib/python3.12/site-packages/airflow/models/taskinstance.py", line 1065, in _email_alert
    send_email(task.email, subject, html_content_err)
  File "/home/airflow/.local/lib/python3.12/site-packages/airflow/utils/email.py", line 80, in send_email
    return backend(
           ^^^^^^^^
  File "/home/airflow/.local/lib/python3.12/site-packages/airflow/utils/email.py", line 154, in send_email_smtp
    send_mime_email(e_from=mail_from, e_to=recipients, mime_msg=msg, conn_id=conn_id, dryrun=dryrun)
  File "/home/airflow/.local/lib/python3.12/site-packages/airflow/utils/email.py", line 281, in send_mime_email
    smtp_conn.login(smtp_user, smtp_password)
  File "/usr/local/lib/python3.12/smtplib.py", line 750, in login
    raise last_exception
  File "/usr/local/lib/python3.12/smtplib.py", line 739, in login
    (code, resp) = self.auth(
                   ^^^^^^^^^^
  File "/usr/local/lib/python3.12/smtplib.py", line 662, in auth
    raise SMTPAuthenticationError(code, resp)
smtplib.SMTPAuthenticationError: (535, b'5.7.8 Username and Password not accepted. For more information, go to\n5.7.8  https://support.google.com/mail/?p=BadCredentials d9443c01a7336-1f9b5b7a8d3sm31226125ad.247 - gsmtp')
[2024-06-20T12:17:57.775+0000] {standard_task_runner.py:110} ERROR - Failed to execute job 271 for task task4 (Bash command failed. The command returned a non-zero exit code 1.; 424)
[2024-06-20T12:17:57.807+0000] {local_task_job_runner.py:240} INFO - Task exited with return code 1
[2024-06-20T12:17:57.822+0000] {taskinstance.py:3503} INFO - 1 downstream tasks scheduled from follow-on schedule check
[2024-06-20T12:17:57.825+0000] {local_task_job_runner.py:222} INFO - ::endgroup::
