[2024-06-20T11:19:31.162+0000] {local_task_job_runner.py:120} INFO - ::group::Pre task execution logs
[2024-06-20T11:19:31.176+0000] {taskinstance.py:2076} INFO - Dependencies all met for dep_context=non-requeueable deps ti=<TaskInstance: emailtest.send_email manual__2024-06-20T11:19:09.007982+00:00 [queued]>
[2024-06-20T11:19:31.181+0000] {taskinstance.py:2076} INFO - Dependencies all met for dep_context=requeueable deps ti=<TaskInstance: emailtest.send_email manual__2024-06-20T11:19:09.007982+00:00 [queued]>
[2024-06-20T11:19:31.181+0000] {taskinstance.py:2306} INFO - Starting attempt 1 of 2
[2024-06-20T11:19:31.189+0000] {taskinstance.py:2330} INFO - Executing <Task(EmailOperator): send_email> on 2024-06-20 11:19:09.007982+00:00
[2024-06-20T11:19:31.194+0000] {warnings.py:112} WARNING - /home/***/.local/lib/python3.12/site-packages/***/task/task_runner/standard_task_runner.py:61: DeprecationWarning: This process (pid=75) is multi-threaded, use of fork() may lead to deadlocks in the child.
  pid = os.fork()

[2024-06-20T11:19:31.195+0000] {standard_task_runner.py:63} INFO - Started process 76 to run task
[2024-06-20T11:19:31.195+0000] {standard_task_runner.py:90} INFO - Running: ['***', 'tasks', 'run', 'emailtest', 'send_email', 'manual__2024-06-20T11:19:09.007982+00:00', '--job-id', '218', '--raw', '--subdir', 'DAGS_FOLDER/emailtest.py', '--cfg-path', '/tmp/tmplgd8wy1_']
[2024-06-20T11:19:31.195+0000] {standard_task_runner.py:91} INFO - Job 218: Subtask send_email
[2024-06-20T11:19:31.221+0000] {task_command.py:426} INFO - Running <TaskInstance: emailtest.send_email manual__2024-06-20T11:19:09.007982+00:00 [running]> on host 055c7aec40d4
[2024-06-20T11:19:31.269+0000] {taskinstance.py:2648} INFO - Exporting env vars: AIRFLOW_CTX_DAG_EMAIL='liviataina.ltab@gmail.com' AIRFLOW_CTX_DAG_OWNER='***' AIRFLOW_CTX_DAG_ID='emailtest' AIRFLOW_CTX_TASK_ID='send_email' AIRFLOW_CTX_EXECUTION_DATE='2024-06-20T11:19:09.007982+00:00' AIRFLOW_CTX_TRY_NUMBER='1' AIRFLOW_CTX_DAG_RUN_ID='manual__2024-06-20T11:19:09.007982+00:00'
[2024-06-20T11:19:31.270+0000] {taskinstance.py:430} INFO - ::endgroup::
[2024-06-20T11:19:31.283+0000] {base.py:84} INFO - Using connection ID 'smtp_default' for task execution.
[2024-06-20T11:19:31.283+0000] {email.py:271} INFO - Email alerting: attempt 1
[2024-06-20T11:19:34.123+0000] {taskinstance.py:441} INFO - ::group::Post task execution logs
[2024-06-20T11:19:34.124+0000] {taskinstance.py:2905} ERROR - Task failed with exception
Traceback (most recent call last):
  File "/home/airflow/.local/lib/python3.12/site-packages/airflow/models/taskinstance.py", line 465, in _execute_task
    result = _execute_callable(context=context, **execute_callable_kwargs)
             ^^^^^^^^^^^^^^^^^^^^^^^^^^^^^^^^^^^^^^^^^^^^^^^^^^^^^^^^^^^^^
  File "/home/airflow/.local/lib/python3.12/site-packages/airflow/models/taskinstance.py", line 432, in _execute_callable
    return execute_callable(context=context, **execute_callable_kwargs)
           ^^^^^^^^^^^^^^^^^^^^^^^^^^^^^^^^^^^^^^^^^^^^^^^^^^^^^^^^^^^^
  File "/home/airflow/.local/lib/python3.12/site-packages/airflow/models/baseoperator.py", line 401, in wrapper
    return func(self, *args, **kwargs)
           ^^^^^^^^^^^^^^^^^^^^^^^^^^^
  File "/home/airflow/.local/lib/python3.12/site-packages/airflow/operators/email.py", line 79, in execute
    send_email(
  File "/home/airflow/.local/lib/python3.12/site-packages/airflow/utils/email.py", line 80, in send_email
    return backend(
           ^^^^^^^^
  File "/home/airflow/.local/lib/python3.12/site-packages/airflow/utils/email.py", line 154, in send_email_smtp
    send_mime_email(e_from=mail_from, e_to=recipients, mime_msg=msg, conn_id=conn_id, dryrun=dryrun)
  File "/home/airflow/.local/lib/python3.12/site-packages/airflow/utils/email.py", line 273, in send_mime_email
    smtp_conn = _get_smtp_connection(smtp_host, smtp_port, smtp_timeout, smtp_ssl)
                ^^^^^^^^^^^^^^^^^^^^^^^^^^^^^^^^^^^^^^^^^^^^^^^^^^^^^^^^^^^^^^^^^^
  File "/home/airflow/.local/lib/python3.12/site-packages/airflow/utils/email.py", line 329, in _get_smtp_connection
    return smtplib.SMTP_SSL(host=host, port=port, timeout=timeout, context=ssl_context)
           ^^^^^^^^^^^^^^^^^^^^^^^^^^^^^^^^^^^^^^^^^^^^^^^^^^^^^^^^^^^^^^^^^^^^^^^^^^^^
  File "/usr/local/lib/python3.12/smtplib.py", line 1022, in __init__
    SMTP.__init__(self, host, port, local_hostname, timeout,
  File "/usr/local/lib/python3.12/smtplib.py", line 255, in __init__
    (code, msg) = self.connect(host, port)
                  ^^^^^^^^^^^^^^^^^^^^^^^^
  File "/usr/local/lib/python3.12/smtplib.py", line 341, in connect
    self.sock = self._get_socket(host, port, self.timeout)
                ^^^^^^^^^^^^^^^^^^^^^^^^^^^^^^^^^^^^^^^^^^
  File "/usr/local/lib/python3.12/smtplib.py", line 1029, in _get_socket
    new_socket = self.context.wrap_socket(new_socket,
                 ^^^^^^^^^^^^^^^^^^^^^^^^^^^^^^^^^^^^
  File "/usr/local/lib/python3.12/ssl.py", line 455, in wrap_socket
    return self.sslsocket_class._create(
           ^^^^^^^^^^^^^^^^^^^^^^^^^^^^^
  File "/usr/local/lib/python3.12/ssl.py", line 1042, in _create
    self.do_handshake()
  File "/usr/local/lib/python3.12/ssl.py", line 1320, in do_handshake
    self._sslobj.do_handshake()
ssl.SSLError: [SSL: WRONG_VERSION_NUMBER] wrong version number (_ssl.c:1000)
[2024-06-20T11:19:34.130+0000] {taskinstance.py:1206} INFO - Marking task as UP_FOR_RETRY. dag_id=emailtest, task_id=send_email, run_id=manual__2024-06-20T11:19:09.007982+00:00, execution_date=20240620T111909, start_date=20240620T111931, end_date=20240620T111934
[2024-06-20T11:19:34.148+0000] {standard_task_runner.py:110} ERROR - Failed to execute job 218 for task send_email ([SSL: WRONG_VERSION_NUMBER] wrong version number (_ssl.c:1000); 76)
[2024-06-20T11:19:34.175+0000] {local_task_job_runner.py:240} INFO - Task exited with return code 1
[2024-06-20T11:19:34.185+0000] {taskinstance.py:3503} INFO - 0 downstream tasks scheduled from follow-on schedule check
[2024-06-20T11:19:34.186+0000] {local_task_job_runner.py:222} INFO - ::endgroup::
